Traceback (most recent call last):
  File "c:\Users\iacop\Desktop\Programmazione\Github\tum-adlr-11\2D_Shape_Completion\main1.py", line 152, in <module>
    main()
  File "c:\Users\iacop\Desktop\Programmazione\Github\tum-adlr-11\2D_Shape_Completion\main1.py", line 57, in main
    mean, std = calculate_mean_std(dataset)
                ^^^^^^^^^^^^^^^^^^^^^^^^^^^
  File "c:\Users\iacop\Desktop\Programmazione\Github\tum-adlr-11\2D_Shape_Completion\main1.py", line 29, in calculate_mean_std
    for inputs, _ in loader:
  File "C:\Users\iacop\anaconda3\Lib\site-packages\torch\utils\data\dataloader.py", line 701, in __next__
    data = self._next_data()
           ^^^^^^^^^^^^^^^^^
  File "C:\Users\iacop\anaconda3\Lib\site-packages\torch\utils\data\dataloader.py", line 1465, in _next_data
    return self._process_data(data)
           ^^^^^^^^^^^^^^^^^^^^^^^^
  File "C:\Users\iacop\anaconda3\Lib\site-packages\torch\utils\data\dataloader.py", line 1491, in _process_data
    data.reraise()
  File "C:\Users\iacop\anaconda3\Lib\site-packages\torch\_utils.py", line 714, in reraise
    raise RuntimeError(msg) from None
RuntimeError: Caught UFuncTypeError in DataLoader worker process 0.
Original Traceback (most recent call last):
  File "C:\Users\iacop\anaconda3\Lib\site-packages\torch\utils\data\_utils\worker.py", line 351, in _worker_loop
    data = fetcher.fetch(index)  # type: ignore[possibly-undefined]
           ^^^^^^^^^^^^^^^^^^^^
  File "C:\Users\iacop\anaconda3\Lib\site-packages\torch\utils\data\_utils\fetch.py", line 52, in fetch
    data = [self.dataset[idx] for idx in possibly_batched_index]
           ^^^^^^^^^^^^^^^^^^^^^^^^^^^^^^^^^^^^^^^^^^^^^^^^^^^^^
  File "C:\Users\iacop\anaconda3\Lib\site-packages\torch\utils\data\_utils\fetch.py", line 52, in <listcomp>
    data = [self.dataset[idx] for idx in possibly_batched_index]
            ~~~~~~~~~~~~^^^^^
  File "c:\Users\iacop\Desktop\Programmazione\Github\tum-adlr-11\2D_Shape_Completion\create_dataset_file.py", line 40, in __getitem__
    target_image /= 255.0  # Scale to [0, 1]
    ^^^^^^^^^^^^^^^^^^^^^
numpy.core._exceptions._UFuncOutputCastingError: Cannot cast ufunc 'divide' output from dtype('float64') to dtype('uint8') with casting rule 'same_kind'
