Traceback (most recent call last):
  File "C:\Users\iacop\anaconda3\Lib\site-packages\wandb\sdk\wandb_config.py", line 165, in __getattr__
    return self.__getitem__(key)
           ^^^^^^^^^^^^^^^^^^^^^
  File "C:\Users\iacop\anaconda3\Lib\site-packages\wandb\sdk\wandb_config.py", line 130, in __getitem__
    return self._items[key]
           ~~~~~~~~~~~^^^^^
KeyError: 'epoch'

The above exception was the direct cause of the following exception:

Traceback (most recent call last):
  File "c:\Users\iacop\Desktop\Programmazione\Github\tum-adlr-11\2D_Shape_Completion\main.py", line 89, in <module>
    for epoch in range(wandb.config.epoch):
                       ^^^^^^^^^^^^^^^^^^
  File "C:\Users\iacop\anaconda3\Lib\site-packages\wandb\sdk\wandb_config.py", line 167, in __getattr__
    raise AttributeError(
AttributeError: <class 'wandb.sdk.wandb_config.Config'> object has no attribute 'epoch'
